Workbook

Sheet 01_README
A1: A AUTO COMPONENTS PVT. LTD.
A2: Manufacturing Capacity Planning, Production Optimization & Make-or-Buy Analysis
A4: PROJECT OVERVIEW
A5: Apex Auto Components Pvt. Ltd. is a fictional automotive component manufacturer and sourcing company managing a portfolio of 500 components used across multiple automotive product families. The company manufactures selected components internally while sourcing others from external suppliers. This project develops an integrated capacity planning and production optimization model to evaluate production capacity, machine and labor utilization, Overall Equipment Effectiveness (OEE), productivity, quality, inventory, costing, pricing, contribution, supplier performance, and make-or-buy decisions.
A7: BUSINESS PROBLEM
A8: Management needs to determine whether existing manufacturing capacity is sufficient to meet component demand, identify production bottlenecks, evaluate machine and labor efficiency, assess the impact of defects and downtime, and determine how limited production capacity should be allocated. The model also evaluates whether selected components should be manufactured internally or purchased from suppliers.
A10: PROJECT OBJECTIVES
A11: Evaluate manufacturing capacity against component demand
A12: Identify machine and labor bottlenecks
A13: Measure machine efficiency and labor efficiency
A14: Calculate OEE using Availability, Performance and Quality
A15: Measure machine and labor productivity
... A25: KEY MODEL ASSUMPTIONS
A26: Planning frequency | B26: Monthly
A27: Number of components | B27: 500
A28: Internally manufactured components | B28: 300
A29: Externally sourced components | B29: 200
A30: Number of production machines | B30: 25
A31: Number of suppliers | B31: 30
A32: Planning horizon | B32: 12 months
A33: Machine efficiency | B33: <100%
A34: Labor efficiency | B34: <100%
A35: Defect rate | B35: >0%
A36: Machine availability | B36: <100%
A37: Demand | B37: Monthly component demand
A38: Inventory | B38: Opening inventory + safety stock
A39: Production quality | B39: Defective and good output tracked separately
A40: Pricing | B40: Selling price and average selling price
A41: Costing | B41: Fixed and variable costs
A42: Dataset | B42: Synthetic / simulated
A44: CORE MODEL LOGIC
A45: Demand → Production/Sourcing Requirement
A46: Production Requirement → Machine & Labor Requirements
A47: Machine/Labor Requirements → Capacity Utilization
A48: Production → Defective & Good Output
A49: Machine Time + Downtime → Availability
A50: Actual Production vs Ideal Production → Performance
A51: Good Output vs Total Output → Quality
A52: Availability × Performance × Quality → OEE
A53: Production + Purchases + Inventory → Closing Inventory
...

Sheet 02_data_dictionary
A1: 1. COMPONENT MASTER
A2: Module | B2: Variable | C2: Definition | D2: Unit | E2: Applies To | F2: Type | G2: Source / Logic | H2: Assumption / Range
A3: Component | B3: Component ID | C3: Unique identifier for each component | D3: — | E3: Both | F3: Generated | G3: Synthetic | H3: C001–C500
A4: Component | B4: Component Name | C4: Name assigned to the component | D4: — | E4: Both | F4: Generated | G4: Synthetic | H4: Component 001–500
A5: Component | B5: Product Family | C5: Automotive system to which component belongs | D5: — | E5: Both | F5: Generated | G5: Synthetic | H5: 5 families
A6: Component | B6: Component Category | C6: Broad type of component | D6: — | E6: Both | F6: Generated | G6: Synthetic | H6: Metal, Plastic, Electrical, etc.
A7: Component | B7: Sourcing Type | C7: Whether component is manufactured or purchased | D7: — | E7: Both | F7: Generated | G7: Synthetic | H7: Make / Buy
A8: Component | B8: Criticality | C8: Operational importance of component | D8: — | E8: Both | F8: Generated | G8: Synthetic | H8: Critical / High / Medium / Low
A9: Component | B9: Monthly Demand | C9: Expected monthly requirement | D9: Units/month | E9: Both | F9: Generated | G9: Synthetic | H9: Demand varies by component
A10: Component | B10: Demand Growth Rate | C10: Expected change in demand | D10: % | E10: Both | F10: Generated | G10: Synthetic | H10: -5% to +20%
A11: Component | B11: Forecast Demand | C11: Demand after applying growth assumption | D11: Units/month | E11: Both | F11: Calculated | G11: Demand × (1 + Growth Rate) | H11: —
A12: Component | B12: Opening Inventory | C12: Inventory available at beginning of period | D12: Units | E12: Both | F12: Generated | G12: Synthetic | H12: Positive
A13: Component | B13: Safety Stock | C13: Minimum desired inventory buffer | D13: Units | E13: Both | F13: Generated | G13: Synthetic | H13: Based on demand
A14: Component | B14: Reorder Point | C14: Inventory level triggering replenishment | D14: Units | E14: Both | F14: Calculated | G14: Demand/lead-time logic | H14: —
A16: 2. MACHINE VARIABLES
A17: Module | B17: Variable | C17: Definition | D17: Unit | E17: Applies To | F17: Type | G17: Source / Logic | H17: Assumption / Range
A18: Machine | B18: Machine ID | C18: Unique machine identifier | D18: — | E18: Make | F18: Generated | G18: Synthetic | H18: M001–M025
A19: Machine | B19: Machine Name | C19: Machine description | D19: — | E19: Make | F19: Generated | G19: Synthetic | H19: Synthetic
A20: Machine | B20: Machine Type | C20: Type of manufacturing equipment | D20: — | E20: Make | F20: Generated | G20: Synthetic | H20: CNC, Press, Molding, etc.
A21: Machine | B21: Production Line | C21: Manufacturing line containing machine | D21: — | E21: Make | F21: Generated | G21: Synthetic | H21: Multiple lines
A22: Machine | B22: Installation Year | C22: Year machine was installed | D22: Year | E22: Make | F22: Generated | G22: Synthetic | H22: 2012–2024
A23: Machine | B23: Machine Age | C23: Age of machine | D23: Years | E23: Make | F23: Calculated | G23: Current year − Installation Year | H23: —
A24: Machine | B24: Scheduled Hours | C24: Total scheduled operating hours | D24: Hours/month | E24: Make | F24: Generated | G24: Synthetic | H24: Based on shifts
A25: Machine | B25: Planned Maintenance | C25: Scheduled maintenance time | D25: Hours/month | E25: Make | F25: Generated | G25: Synthetic | H25: >0
A26: Machine | B26: Planned Downtime | C26: Planned non-operating time | D26: Hours/month | E26: Make | F26: Generated | G26: Synthetic | H26: >0
A27: Machine | B27: Machine Efficiency | C27: Efficiency of machine relative to theoretical performance | D27: % | E27: Make | F27: Generated | G27: Synthetic | H27: 75%–97%
A28: Machine | B28: Available Hours | C28: Hours available after planned downtime | D28: Hours/month | E28: Make | F28: Calculated | G28: Scheduled Hours − Planned Downtime | H28: —
A30: 3. PRODUCTION VARIABLES
A31: Module | B31: Variable | C31: Definition | D31: Unit | E31: Applies To | F31: Type | G31: Source / Logic | H31: Assumption / Range
A32: Production | B32: Assigned Machine | C32: Machine used to manufacture component | D32: — | E32: Make | F32: Generated | G32: Machine assignment | H32: M001–M025
A33: Production | B33: Ideal Cycle Time | C33: Theoretical time required to produce one unit | D33: min/unit | E33: Make | F33: Generated | G33: Synthetic | H33: 0.5–30 min
A34: Production | B34: Actual Cycle Time | C34: Observed production time per unit | D34: min/unit | E34: Make | F34: Calculated | G34: Ideal Cycle Time adjusted for performance | H34: > Ideal
A35: Production | B35: Setup Time | C35: Time required to prepare machine before production | D35: min | E35: Make | F35: Generated | G35: Synthetic | H35: 15–120 min
A36: Production | B36: Changeover Time | C36: Time required to switch between components | D36: min | E36: Make | F36: Generated | G36: Synthetic | H36: 10–90 min
A37: Production | B37: Planned Production Time | C37: Time allocated for production | D37: Hours/month | E37: Make | F37: Calculated | G37: Available production schedule | H37: —
A38: Production | B38: Downtime | C38: Unplanned machine downtime | D38: Hours/month | E38: Make | F38: Generated | G38: Synthetic | H38: >0
A39: Production | B39: Operating Time | C39: Actual time machine operates | D39: Hours/month | E39: Make | F39: Calculated | G39: Planned Production Time − Downtime | H39: —
A40: Production | B40: Planned Production Quantity | C40: Quantity scheduled for production | D40: Units | E40: Make | F40: Calculated | G40: Demand/inventory requirement | H40: —
A41: Production | B41: Actual Production | C41: Total units actually produced | D41: Units | E41: Make | F41: Calculated | G41: Production process | H41: —
A42: Production | B42: Defective Production | C42: Units failing quality requirements | D42: Units | E42: Make | F42: Calculated | G42: Actual Production × Defect Rate | H42: —
...

Sheet 03_raw_components
A1: Component_ID | B1: Component_Name | C1: Product_Family | D1: Category | E1: Size | F1: Sourcing_Type | G1: Criticality | H1: Monthly_Demand | I1: Demand_Growth_Rate | J1: Forecast_Demand | K1: Opening_Inventory | L1: Safety_Stock | M1: Assigned_Machine | N1: Ideal_Cycle_Time_Min | O1: Actual_Cycle_Time_Min | P1: Setup_Time_Min | Q1: Changeover_Time_Min | R1: Operators_Required | S1: Labor_Hours_Per_Unit | T1: Defect_Rate | U1: Labor_Efficiency | V1: Assigned_Supplier | W1: Supplier_Capacity | X1: Purchase_Price_Index | Y1: Lead_Time_Days | Z1: MOQ | AA1: Supplier_Defect_Rate | AB1: Delivery_Reliability | AC1: Transportation_Cost | AD1: Payment_Terms_Days | AE1: Purchase_Price_Per_Unit | AF1: Landed_Cost_Per_Unit | AG1: Effective_Cost_Per_Unit | AH1: Raw_Material_Cost_Per_Unit | AI1: Direct_Labor_Cost_Per_Unit | AJ1: Machine_Cost_Per_Unit | AK1: Variable_Overhead_Per_Unit | AL1: Variable_Cost_Per_Unit | AM1: Target_Contribution_Margin | AN1: Selling_Price_Per_Unit | AO1: Contribution_Per_Unit | AP1: Contribution_Margin | AQ1: Variable_Cost_Ratio | AR1: Annual_Demand | AS1: Average_Monthly_Demand | AT1: Demand_Variability | AU1: Net_Requirement | AV1: Required_Good_Units | AW1: Gross_Requirement | AX1: Planned_Production_or_Procurement | AY1: Required_Machine_Hours | AZ1: Machine_Efficiency | BA1: Required_Labor_Hours | BB1: Quality_Rate | BC1: Performance_Rate | BD1: Availability_Rate | BE1: OEE
A2: C001 | B2: Component 001 | C2: Powertrain | D2: Electrical | E2: Large | F2: Make | G2: Medium | H2: 557 | I2: 0.17880343 | J2: 657 | K2: 1130 | L2: 98 | M2: M014 | N2: 6.46 | O2: 6.99 | P2: 96.9 | Q2: 45.7 | R2: 5 | S2: 0.1534 | T2: 0.0151 | U2: 0.9304 | AH2: 1600.26 | AI2: 60.86 | AJ2: 170.95 | AK2: 154.14 | AL2: 1986.21 | AM2: 0.32613861 | AN2: 2947.51 | AO2: 961.3 | AP2: 0.3261 | AQ2: 0.6739 | AR2: 5924 | AS2: 494 | AT2: 0.1725 | AU2: 4892 | AV2: 4892 | AW2: 4967 | AX2: 1163 | AY2: 135.49 | AZ2: 0.8403 | BA2: 178.4 | BB2: 0.9849 | BC2: 0.9241774 | BD2: 0.8592 | BE2: 0.7821
A3: C002 | B3: Component 002 | C3: Chassis | D3: Metal | E3: Small | F3: Make | G3: Low | H3: 688 | I3: 0.13447423 | J3: 781 | K3: 4186 | L3: 1546 | M3: M002 | N3: 4.93 | O3: 5.13 | P3: 43.1 | Q3: 39 | R3: 2 | S3: 0.0799 | T3: 0.0054 | U3: 0.8561 | AH3: 201.93 | AI3: 36.85 | AJ3: 58.24 | AK3: 16.47 | AL3: 313.49 | AM3: 0.25568216 | AN3: 421.18 | AO3: 107.69 | AP3: 0.2557 | AQ3: 0.7443 | AR3: 45830 | AS3: 3819 | AT3: 0.2459 | AU3: 43190 | AV3: 43190 | AW3: 43424 | AX3: 1831 | AY3: 156.55 | AZ3: 0.8418 | BA3: 146.3 | BB3: 0.9946 | BC3: 0.96101365 | BD3: 0.8367 | BE3: 0.7997
A4: C003 | B4: Component 003 | C4: Electrical Systems | D4: Metal | E4: Small | F4: Make | G4: Medium | H4: 284 | I4: 0.035469917 | J4: 294 | K4: 7776 | L4: 1143 | M4: M020 | N4: 6.08 | O4: 6.45 | P4: 23.6 | Q4: 42.1 | R4: 1 | S4: 0.0214 | T4: 0.0169 | U4: 0.9409 | AH4: 641.36 | AI4: 8.77 | AJ4: 155.81 | AK4: 63.29 | AL4: 869.23 | AM4: 0.23663104 | AN4: 1138.68 | AO4: 269.45 | AP4: 0.2366 | AQ4: 0.7634 | AR4: 77893 | AS4: 6491 | AT4: 0.1428 | AU4: 71260 | AV4: 71260 | AW4: 72485 | AX4: 6001 | AY4: 645.11 | AZ4: 0.9246 | BA4: 128.42 | BB4: 0.9831 | BC4: 0.94263566 | BD4: 0.8338 | BE4: 0.7727
A5: C004 | B5: Component 004 | C5: Powertrain | D5: Metal | E5: Large | F5: Make | G5: High | H5: 1473 | I5: 0.072903969 | J5: 1580 | K5: 2893 | L5: 253 | M5: M008 | N5: 0.79 | O5: 0.81 | P5: 86.5 | Q5: 48 | R5: 4 | S5: 0.334 | T5: 0.0069 | U5: 0.8797 | AH5: 940.04 | AI5: 103.1 | AJ5: 16.91 | AK5: 83.21 | AL5: 1143.26 | AM5: 0.24940309 | AN5: 1523.13 | AO5: 379.87 | AP5: 0.2494 | AQ5: 0.7506 | AR5: 18650 | AS5: 1554 | AT5: 0.1407 | AU5: 16010 | AV5: 16010 | AW5: 16121 | AX5: 4681 | AY5: 63.19 | AZ5: 0.9164 | BA5: 1563.45 | BB5: 0.9931 | BC5: 0.97530864 | BD5: 0.9076 | BE5: 0.8791
A6: C005 | B6: Component 005 | C6: Powertrain | D6: Metal | E6: Medium | F6: Make | G6: Medium | H6: 1301 | I6: 0.015223406 | J6: 1321 | K6: 2586 | L6: 305 | M6: M009 | N6: 1.02 | O6: 1.13 | P6: 55.9 | Q6: 32.5 | R6: 3 | S6: 0.1816 | T6: 0.0276 | U6: 0.8873 | AH6: 960.93 | AI6: 77.48 | AJ6: 13.15 | AK6: 57.44 | AL6: 1109 | AM6: 0.21606907 | AN6: 1414.67 | AO6: 305.67 | AP6: 0.2161 | AQ6: 0.7839 | AR6: 15691 | AS6: 1308 | AT6: 0.1385 | AU6: 13410 | AV6: 13410 | AW6: 13791 | AX6: 4201 | AY6: 79.12 | AZ6: 0.9374 | BA6: 762.9 | BB6: 0.9724 | BC6: 0.90265487 | BD6: 0.8745 | BE6: 0.7676
A7: C006 | B7: Component 006 | C7: Interior | D7: Metal | E7: Medium | F7: Make | G7: Medium | H7: 835 | I7: 0.11060482 | J7: 927 | K7: 8535 | L7: 1008 | M7: M020 | N7: 3.27 | O7: 3.41 | P7: 73.5 | Q7: 51.9 | R7: 3 | S7: 0.15 | T7: 0.0161 | U7: 0.94 | AH7: 696.17 | AI7: 73.54 | AJ7: 65.36 | AK7: 62.14 | AL7: 897.21 | AM7: 0.20133323 | AN7: 1123.38 | AO7: 226.17 | AP7: 0.2013 | AQ7: 0.7987 | AR7: 45062 | AS7: 3755 | AT7: 0.1685 | AU7: 37535 | AV7: 37535 | AW7: 38149 | AX7: 3158 | AY7: 179.48 | AZ7: 0.9246 | BA7: 473.7 | BB7: 0.9839 | BC7: 0.95894428 | BD7: 0.8338 | BE7: 0.7867
A8: C007 | B8: Component 007 | C8: Electrical Systems | D8: Electrical | E8: Medium | F8: Make | G8: Medium | H8: 1428 | I8: 0.15280104 | J8: 1646 | K8: 1286 | L8: 361 | M8: M014 | N8: 2.32 | O8: 2.66 | P8: 80 | Q8: 59.4 | R8: 4 | S8: 0.1866 | T8: 0.0056 | U8: 0.8688 | AH8: 1046.3 | AI8: 78.43 | AJ8: 52.39 | AK8: 68 | AL8: 1245.12 | AM8: 0.27075992 | AN8: 1707.42 | AO8: 462.3 | AP8: 0.2708 | AQ8: 0.7292 | AR8: 15931 | AS8: 1328 | AT8: 0.1549 | AU8: 15006 | AV8: 15006 | AW8: 15091 | AX8: 3535 | AY8: 156.72 | AZ8: 0.8403 | BA8: 659.63 | BB8: 0.9944 | BC8: 0.87218045 | BD8: 0.8592 | BE8: 0.7452
A9: C008 | B9: Component 008 | C9: Electrical Systems | D9: Electrical | E9: Medium | F9: Make | G9: High | H9: 511 | I9: -0.0248055 | J9: 498 | K9: 7930 | L9: 1171 | M9: M013 | N9: 4.22 | O9: 4.52 | P9: 77.5 | Q9: 44.1 | R9: 2 | S9: 0.0694 | T9: 0.0241 | U9: 0.8798 | AH9: 1702.51 | AI9: 32.19 | AJ9: 60.19 | AK9: 191.29 | AL9: 1986.18 | AM9: 0.21713344 | AN9: 2537.06 | AO9: 550.88 | AP9: 0.2171 | AQ9: 0.7829 | AR9: 46730 | AS9: 3894 | AT9: 0.2296 | AU9: 39971 | AV9: 39971 | AW9: 40958 | AX9: 9219 | AY9: 694.5 | AZ9: 0.9606 | BA9: 639.8 | BB9: 0.9759 | BC9: 0.93362832 | BD9: 0.8643 | BE9: 0.7875
A10: C009 | B10: Component 009 | C10: Powertrain | D10: Electrical | E10: Small | F10: Make | G10: High | H10: 189 | I10: 0.035156142 | J10: 196 | K10: 6543 | L10: 815 | M10: M014 | N10: 4.7 | O10: 5.59 | P10: 30.3 | Q10: 29.1 | R10: 2 | S10: 0.0538 | T10: 0.0139 | U10: 0.8677 | AH10: 1108.54 | AI10: 25.65 | AJ10: 161.63 | AK10: 150.75 | AL10: 1446.57 | AM10: 0.22186542 | AN10: 1859.02 | AO10: 412.45 | AP10: 0.2219 | AQ10: 0.7781 | AR10: 40692 | AS10: 3391 | AT10: 0.1659 | AU10: 34964 | AV10: 34964 | AW10: 35457 | AX10: 8306 | AY10: 773.84 | AZ10: 0.8403 | BA10: 446.86 | BB10: 0.9861 | BC10: 0.84078712 | BD10: 0.8592 | BE10: 0.7124
A11: C010 | B11: Component 010 | C11: Electrical Systems | D11: Electrical | E11: Small | F11: Make | G11: Low | H11: 1728 | I11: 0.15087023 | J11: 1989 | K11: 4604 | L11: 1505 | M11: M013 | N11: 5.5 | O11: 6.48 | P11: 16.8 | Q11: 36.1 | R11: 1 | S11: 0.0321 | T11: 0.0037 | U11: 0.8661 | AH11: 1347.52 | AI11: 11.09 | AJ11: 174.96 | AK11: 84.44 | AL11: 1618.01 | AM11: 0.31418902 | AN11: 2359.27 | AO11: 741.26 | AP11: 0.3142 | AQ11: 0.6858 | AR11: 77295 | AS11: 6441 | AT11: 0.1663 | AU11: 74196 | AV11: 74196 | AW11: 74472 | AX11: 16762 | AY11: 1810.3 | AZ11: 0.9606 | BA11: 538.06 | BB11: 0.9963 | BC11: 0.84876543 | BD11: 0.8643 | BE11: 0.7309
A12: C011 | B12: Component 011 | C12: Powertrain | D12: Electrical | E12: Large | F12: Make | G12: Low | H12: 1477 | I12: 0.012504112 | J12: 1495 | K12: 2600 | L12: 412 | M12: M002 | N12: 16.72 | O12: 18.04 | P12: 78.4 | Q12: 31.2 | R12: 3 | S12: 0.1197 | T12: 0.0189 | U12: 0.8947 | AH12: 1027.54 | AI12: 40.99 | AJ12: 421.78 | AK12: 174.15 | AL12: 1664.46 | AM12: 0.39213433 | AN12: 2738.2 | AO12: 1073.74 | AP12: 0.3921 | AQ12: 0.6079 | AR12: 24054 | AS12: 2004 | AT12: 0.1035 | AU12: 21866 | AV12: 21866 | AW12: 22287 | AX12: 939 | AY12: 282.33 | AZ12: 0.8418 | BA12: 112.4 | BB12: 0.9811 | BC12: 0.92682927 | BD12: 0.8367 | BE12: 0.7608
A13: C012 | B13: Component 012 | C13: Interior | D13: Metal | E13: Small | F13: Make | G13: Medium | H13: 454 | I13: -0.024219033 | J13: 443 | K13: 5920 | L13: 1705 | M13: M024 | N13: 2.08 | O13: 2.42 | P13: 17.8 | Q13: 23.6 | R13: 2 | S13: 0.0411 | T13: 0.0078 | U13: 0.9456 | AH13: 218.04 | AI13: 17.35 | AJ13: 46.58 | AK13: 24.41 | AL13: 306.38 | AM13: 0.3009093 | AN13: 438.26 | AO13: 131.88 | AP13: 0.3009 | AQ13: 0.6991 | AR13: 64057 | AS13: 5338 | AT13: 0.2471 | AU13: 59842 | AV13: 59842 | AW13: 60312 | AX13: 8734 | AY13: 352.27 | AZ13: 0.9238 | BA13: 358.97 | BB13: 0.9922 | BC13: 0.85950413 | BD13: 0.8746 | BE13: 0.7459
... A301: C300 | B301: Component 300 | C301: Chassis | D301: Metal | E301: Small | F301: Make | G301: High | H301: 2254 | I301: 0.069109247 | J301: 2410 | K301: 11861 | L301: 2327 | M301: M001 | N301: 3.87 | O301: 4.31 | P301: 37.5 | Q301: 20.4 | R301: 1 | S301: 0.0636 | T301: 0.0039 | U301: 0.8454 | AH301: 229.57 | AI301: 31.08 | AJ301: 124.28 | AK301: 34.8 | AL301: 419.73 | AM301: 0.26848031 | AN301: 573.78 | AO301: 154.05 | AP301: 0.2685 | AQ301: 0.7315 | AR301: 79420 | AS301: 6618 | AT301: 0.182 | AU301: 69886 | AV301: 69886 | AW301: 70160 | AX301: 2320 | AY301: 166.65 | AZ301: 0.8514 | BA301: 147.55 | BB301: 0.9961 | BC301: 0.89791183 | BD301: 0.8657 | BE301: 0.7743
A302: C301 | B302: Component 301 | C302: Body & Exterior | D302: Electrical | E302: Medium | F302: Buy | G302: Medium | H302: 1225 | I302: -0.0030392869 | J302: 1221 | K302: 3230 | L302: 648 | V302: SUP029 | W302: 16296 | X302: 1.0170161 | Y302: 29 | Z302: 4665 | AA302: 0.01207769 | AB302: 0.88415855 | AC302: 24.379243 | AD302: 90 | AE302: 1166.46 | AF302: 1190.84 | AG302: 1205.4 | AH302: 880.79 | AL302: 1205.4 | AM302: 0.32909928 | AN302: 1796.69 | AO302: 591.29 | AP302: 0.3291 | AQ302: 0.6709 | AR302: 22833 | AS302: 1903 | AT302: 0.2043 | AU302: 20251 | AV302: 20251 | AW302: 20499 | AX302: 20499 | AY302: 0 | BA302: 0 | BB302: 0 | BC302: 0 | BD302: 0 | BE302: 0
A303: C302 | B303: Component 302 | C303: Interior | D303: Metal | E303: Large | F303: Buy | G303: Medium | H303: 1381 | I303: 0.01048292 | J303: 1395 | K303: 949 | L303: 162 | V303: SUP016 | W303: 15173 | X303: 1.0157369 | Y303: 28 | Z303: 2138 | AA303: 0.036051469 | AB303: 0.89452049 | AC303: 4.5311943 | AD303: 15 | AE303: 1085.07 | AF303: 1089.6 | AG303: 1130.35 | AH303: 323.48 | AL303: 1130.35 | AM303: 0.21773567 | AN303: 1444.97 | AO303: 314.62 | AP303: 0.2177 | AQ303: 0.7823 | AR303: 5066 | AS303: 422 | AT303: 0.2109 | AU303: 4279 | AV303: 4279 | AW303: 4439 | AX303: 4439 | AY303: 0 | BA303: 0 | BB303: 0 | BC303: 0 | BD303: 0 | BE303: 0
A304: C303 | B304: Component 303 | C304: Body & Exterior | D304: Electrical | E304: Medium | F304: Buy | G304: Medium | H304: 2494 | I304: 0.13016379 | J304: 2819 | K304: 3348 | L304: 946 | V304: SUP019 | W304: 22675 | X304: 0.90071292 | Y304: 4 | Z304: 1736 | AA304: 0.012823939 | AB304: 0.85516417 | AC304: 16.01998 | AD304: 30 | AE304: 159.44 | AF304: 175.46 | AG304: 177.74 | AH304: 793.66 | AL304: 177.74 | AM304: 0.20056355 | AN304: 222.33 | AO304: 44.59 | AP304: 0.2006 | AQ304: 0.7994 | AR304: 45573 | AS304: 3798 | AT304: 0.2458 | AU304: 43171 | AV304: 43171 | AW304: 43732 | AX304: 43732 | AY304: 0 | BA304: 0 | BB304: 0 | BC304: 0 | BD304: 0 | BE304: 0
A305: C304 | B305: Component 304 | C305: Powertrain | D305: Electrical | E305: Large | F305: Buy | G305: Medium | H305: 1060 | I305: 0.029396699 | J305: 1091 | K305: 2845 | L305: 399 | V305: SUP004 | W305: 7747 | X305: 0.94654474 | Y305: 17 | Z305: 3105 | AA305: 0.0095876037 | AB305: 0.92199282 | AC305: 15.625535 | AD305: 45 | AE305: 941.56 | AF305: 957.19 | AG305: 966.45 | AH305: 2403.32 | AL305: 966.45 | AM305: 0.2284567 | AN305: 1252.62 | AO305: 286.17 | AP305: 0.2285 | AQ305: 0.7715 | AR305: 17478 | AS305: 1456 | AT305: 0.1775 | AU305: 15032 | AV305: 15032 | AW305: 15178 | AX305: 15178 | AY305: 0 | BA305: 0 | BB305: 0 | BC305: 0 | BD305: 0 | BE305: 0
A306: C305 | B306: Component 305 | C306: Electrical Systems | D306: Metal | E306: Small | F306: Buy | G306: Medium | H306: 1817 | I306: 0.066742 | J306: 1938 | K306: 12975 | L306: 1612 | V306: SUP003 | W306: 11420 | X306: 1.0469926 | Y306: 28 | Z306: 4217 | AA306: 0.0022685196 | AB306: 0.85322874 | AC306: 14.069817 | AD306: 30 | AE306: 613.25 | AF306: 627.32 | AG306: 628.74 | AH306: 581.37 | AL306: 628.74 | AM306: 0.21037516 | AN306: 796.25 | AO306: 167.51 | AP306: 0.2104 | AQ306: 0.7896 | AR306: 95942 | AS306: 7995 | AT306: 0.1381 | AU306: 84579 | AV306: 84579 | AW306: 84771 | AX306: 84771 | AY306: 0 | BA306: 0 | BB306: 0 | BC306: 0 | BD306: 0 | BE306: 0
A307: C306 | B307: Component 306 | C307: Interior | D307: Metal | E307: Large | F307: Buy | G307: Low | H307: 1136 | I307: 0.16067798 | J307: 1319 | K307: 1833 | L307: 478 | V307: SUP017 | W307: 11776 | X307: 1.1272059 | Y307: 11 | Z307: 1382 | AA307: 0.002264181 | AB307: 0.92150462 | AC307: 11.600453 | AD307: 90 | AE307: 979.25 | AF307: 990.85 | AG307: 993.1 | AH307: 297.58 | AL307: 993.1 | AM307: 0.20372816 | AN307: 1247.19 | AO307: 254.09 | AP307: 0.2037 | AQ307: 0.7963 | AR307: 20103 | AS307: 1675 | AT307: 0.1902 | AU307: 18748 | AV307: 18748 | AW307: 18791 | AX307: 18791 | AY307: 0 | BA307: 0 | BB307: 0 | BC307: 0 | BD307: 0 | BE307: 0
A308: C307 | B308: Component 307 | C308: Body & Exterior | D308: Electrical | E308: Medium | F308: Buy | G308: Low | H308: 1471 | I308: 0.11878502 | J308: 1646 | K308: 5988 | L308: 404 | V308: SUP017 | W308: 11776 | X308: 1.1272059 | Y308: 11 | Z308: 1382 | AA308: 0.002264181 | AB308: 0.92150462 | AC308: 11.600453 | AD308: 90 | AE308: 1753.97 | AF308: 1765.57 | AG308: 1769.58 | AH308: 1125.88 | AL308: 1769.58 | AM308: 0.25621271 | AN308: 2379.15 | AO308: 609.57 | AP308: 0.2562 | AQ308: 0.7438 | AR308: 49420 | AS308: 4118 | AT308: 0.0916 | AU308: 43836 | AV308: 43836 | AW308: 43935 | AX308: 43935 | AY308: 0 | BA308: 0 | BB308: 0 | BC308: 0 | BD308: 0 | BE308: 0
A309: C308 | B309: Component 308 | C309: Powertrain | D309: Metal | E309: Large | F309: Buy | G309: Low | H309: 674 | I309: -0.0082617278 | J309: 668 | K309: 1829 | L309: 597 | V309: SUP012 | W309: 15965 | X309: 1.1548851 | Y309: 3 | Z309: 2790 | AA309: 0.030909832 | AB309: 0.92857881 | AC309: 19.732245 | AD309: 45 | AE309: 1274.93 | AF309: 1294.66 | AG309: 1335.96 | AH309: 500.04 | AL309: 1335.96 | AM309: 0.37695963 | AN309: 2144.26 | AO309: 808.3 | AP309: 0.377 | AQ309: 0.623 | AR309: 18277 | AS309: 1523 | AT309: 0.2326 | AU309: 17045 | AV309: 17045 | AW309: 17589 | AX309: 17589 | AY309: 0 | BA309: 0 | BB309: 0 | BC309: 0 | BD309: 0 | BE309: 0
A310: C309 | B310: Component 309 | C310: Body & Exterior | D310: Electrical | E310: Medium | F310: Buy | G310: Low | H310: 193 | I310: 0.017242008 | J310: 196 | K310: 6621 | L310: 608 | V310: SUP028 | W310: 22340 | X310: 0.88970772 | Y310: 3 | Z310: 4593 | AA310: 0.014365189 | AB310: 0.9545088 | AC310: 16.941557 | AD310: 45 | AE310: 335.41 | AF310: 352.35 | AG310: 357.49 | AH310: 1360.41 | AL310: 357.49 | AM310: 0.27676491 | AN310: 494.29 | AO310: 136.8 | AP310: 0.2768 | AQ310: 0.7232 | AR310: 48367 | AS310: 4031 | AT310: 0.1003 | AU310: 42354 | AV310: 42354 | AW310: 42971 | AX310: 42971 | AY310: 0 | BA310: 0 | BB310: 0 | BC310: 0 | BD310: 0 | BE310: 0
A311: C310 | B311: Component 310 | C311: Electrical Systems | D311: Electrical | E311: Small | F311: Buy | G311: Medium | H311: 1052 | I311: 0.068991933 | J311: 1125 | K311: 7663 | L311: 834 | V311: SUP030 | W311: 10895 | X311: 1.0524555 | Y311: 4 | Z311: 4993 | AA311: 0.026513928 | AB311: 0.94364937 | AC311: 21.875854 | AD311: 60 | AE311: 173.63 | AF311: 195.5 | AG311: 200.83 | AH311: 734 | AL311: 200.83 | AM311: 0.1969801 | AN311: 250.09 | AO311: 49.26 | AP311: 0.197 | AQ311: 0.803 | AR311: 41795 | AS311: 3483 | AT311: 0.1357 | AU311: 34966 | AV311: 34966 | AW311: 35918 | AX311: 35918 | AY311: 0 | BA311: 0 | BB311: 0 | BC311: 0 | BD311: 0 | BE311: 0
A312: C311 | B312: Component 311 | C312: Electrical Systems | D312: Electrical | E312: Small | F312: Buy | G312: Low | H312: 1740 | I312: 0.15554497 | J312: 2011 | K312: 13290 | L312: 2657 | V312: SUP029 | W312: 16296 | X312: 1.0170161 | Y312: 29 | Z312: 4665 | AA312: 0.01207769 | AB312: 0.88415855 | AC312: 24.379243 | AD312: 90 | AE312: 909.3 | AF312: 933.68 | AG312: 945.09 | AH312: 1198.11 | AL312: 945.09 | AM312: 0.16924292 | AN312: 1137.62 | AO312: 192.53 | AP312: 0.1692 | AQ312: 0.8308 | AR312: 98154 | AS312: 8180 | AT312: 0.2187 | AU312: 87521 | AV312: 87521 | AW312: 88591 | AX312: 88591 | AY312: 0 | BA312: 0 | BB312: 0 | BC312: 0 | BD312: 0 | BE312: 0
A313: C312 | B313: Component 312 | C313: Powertrain | D313: Electrical | E313: Medium | F313: Buy | G313: Low | H313: 1120 | I313: 0.13850576 | J313: 1275 | K313: 3444 | L313: 414 | V313: SUP014 | W313: 23141 | X313: 0.85573258 | Y313: 9 | Z313: 1778 | AA313: 0.030710943 | AB313: 0.88203174 | AC313: 3.7705379 | AD313: 45 | AE313: 124.14 | AF313: 127.91 | AG313: 131.96 | AH313: 1641.12 | AL313: 131.96 | AM313: 0.32403904 | AN313: 195.22 | AO313: 63.26 | AP313: 0.324 | AQ313: 0.676 | AR313: 23792 | AS313: 1983 | AT313: 0.1815 | AU313: 20762 | AV313: 20762 | AW313: 21420 | AX313: 21420 | AY313: 0 | BA313: 0 | BB313: 0 | BC313: 0 | BD313: 0 | BE313: 0
... A501: C500 | B501: Component 500 | C501: Powertrain | D501: Metal | E501: Small | F501: Buy | G501: Medium | H501: 462 | I501: -0.021639796 | J501: 452 | K501: 17582 | L501: 1443 | V501: SUP026 | W501: 6154 | X501: 1.1425297 | Y501: 24 | Z501: 3291 | AA501: 0.035735264 | AB501: 0.96912998 | AC501: 23.519605 | AD501: 60 | AE501: 661.78 | AF501: 685.3 | AG501: 710.7 | AH501: 810.21 | AL501: 710.7 | AM501: 0.36616473 | AN501: 1121.27 | AO501: 410.57 | AP501: 0.3662 | AQ501: 0.6338 | AR501: 94140 | AS501: 7845 | AT501: 0.1418 | AU501: 78001 | AV501: 78001 | AW501: 80892 | AX501: 80892 | AY501: 0 | BA501: 0 | BB501: 0 | BC501: 0 | BD501: 0 | BE501: 0

Sheet 04_raw_machines
A1: Machine_ID | B1: Machine_Efficiency | C1: Planned_Downtime_Rate | D1: Unplanned_Downtime_Rate | E1: Scheduled_Hours | F1: Planned_Downtime_Hours | G1: Unplanned_Downtime_Hours | H1: Available_Production_Hours | I1: Required_Machine_Hours | J1: Machine_Utilization | K1: Capacity_Surplus_Shortage_Hours | L1: Average_Availability | M1: Average_Performance | N1: Average_Quality | O1: Average_OEE | P1: Capacity_Status
A2: M014 | B2: 0.8403 | C2: 0.0675 | D2: 0.0733 | E2: 4800 | F2: 324 | G2: 351.84 | H2: 4124.16 | I2: 4175.48 | J2: 1.0124 | K2: -51.32 | L2: 0.8592 | M2: 0.88754335 | N2: 0.98893 | O2: 0.75417 | P2: High Utilization
A3: M002 | B3: 0.8418 | C3: 0.0886 | D3: 0.0747 | E3: 4800 | F3: 425.28 | G3: 358.56 | H3: 4016.16 | I3: 4174.61 | J3: 1.0395 | K3: -158.45 | L3: 0.8367 | M3: 0.89980774 | N3: 0.98745625 | O3: 0.74339375 | P3: High Utilization
A4: M020 | B4: 0.9246 | C4: 0.0902 | D4: 0.076 | E4: 4800 | F4: 432.96 | G4: 364.8 | H4: 4002.24 | I4: 4175.19 | J4: 1.0432 | K4: -172.95 | L4: 0.8338 | M4: 0.91335563 | N4: 0.98713077 | O4: 0.75172308 | P4: High Utilization
A5: M008 | B5: 0.9164 | C5: 0.0577 | D5: 0.0347 | E5: 4800 | F5: 276.96 | G5: 166.56 | H5: 4356.48 | I5: 4175.79 | J5: 0.9585 | K5: 180.69 | L5: 0.9076 | M5: 0.91668988 | N5: 0.98773 | O5: 0.82191 | P5: High Utilization
A6: M009 | B6: 0.9374 | C6: 0.0683 | D6: 0.0572 | E6: 4800 | F6: 327.84 | G6: 274.56 | H6: 4197.6 | I6: 4175.89 | J6: 0.9948 | K6: 21.71 | L6: 0.8745 | M6: 0.89300765 | N6: 0.97657143 | O6: 0.76257143 | P6: High Utilization
A7: M013 | B7: 0.9606 | C7: 0.0687 | D7: 0.067 | E7: 4800 | F7: 329.76 | G7: 321.6 | H7: 4148.64 | I7: 4175.77 | J7: 1.0065 | K7: -27.13 | L7: 0.8643 | M7: 0.91872262 | N7: 0.983925 | O7: 0.7811375 | P7: High Utilization
A8: M024 | B8: 0.9238 | C8: 0.0576 | D8: 0.0678 | E8: 4800 | F8: 276.48 | G8: 325.44 | H8: 4198.08 | I8: 4175.52 | J8: 0.9946 | K8: 22.56 | L8: 0.8746 | M8: 0.89128856 | N8: 0.98666667 | O8: 0.76913333 | P8: High Utilization
A9: M004 | B9: 0.8434 | C9: 0.0899 | D9: 0.0603 | E9: 4800 | F9: 431.52 | G9: 289.44 | H9: 4079.04 | I9: 4174.75 | J9: 1.0235 | K9: -95.71 | L9: 0.8498 | M9: 0.89109387 | N9: 0.98591429 | O9: 0.74658571 | P9: High Utilization
A10: M011 | B10: 0.8565 | C10: 0.0854 | D10: 0.0383 | E10: 4800 | F10: 409.92 | G10: 183.84 | H10: 4206.24 | I10: 4175.72 | J10: 0.9927 | K10: 30.52 | L10: 0.8763 | M10: 0.89317048 | N10: 0.98323333 | O10: 0.769675 | P10: High Utilization
A11: M016 | B11: 0.9463 | C11: 0.0595 | D11: 0.0699 | E11: 4800 | F11: 285.6 | G11: 335.52 | H11: 4178.88 | I11: 4174.23 | J11: 0.9989 | K11: 4.65 | L11: 0.8706 | M11: 0.90652802 | N11: 0.98451818 | O11: 0.7769 | P11: High Utilization
A12: M001 | B12: 0.8514 | C12: 0.0683 | D12: 0.066 | E12: 4800 | F12: 327.84 | G12: 316.8 | H12: 4155.36 | I12: 4174.77 | J12: 1.0047 | K12: -19.41 | L12: 0.8657 | M12: 0.89089217 | N12: 0.98706316 | O12: 0.76129474 | P12: High Utilization
A13: M022 | B13: 0.8309 | C13: 0.0553 | D13: 0.0343 | E13: 4800 | F13: 265.44 | G13: 164.64 | H13: 4369.92 | I13: 4175.37 | J13: 0.9555 | K13: 194.55 | L13: 0.9104 | M13: 0.90754731 | N13: 0.98618 | O13: 0.81477333 | P13: High Utilization
... A26: M012 | B26: 0.8801 | C26: 0.0825 | D26: 0.0378 | E26: 4800 | F26: 396 | G26: 181.44 | H26: 4222.56 | I26: 4175.96 | J26: 0.989 | K26: 46.6 | L26: 0.8797 | M26: 0.88822302 | N26: 0.98475 | O26: 0.769425 | P26: High Utilization

Sheet 05_raw_supplier
A1: Supplier_ID | B1: Supplier_Name | C1: Supplier_Category | D1: Supplier_Capacity | E1: Purchase_Price_Index | F1: Lead_Time_Days | G1: MOQ | H1: Supplier_Defect_Rate | I1: Delivery_Reliability | J1: Transportation_Cost | K1: Payment_Terms_Days
A2: SUP001 | B2: Supplier 01 | C2: Domestic | D2: 5860 | E2: 0.87337392 | F2: 10 | G2: 3872 | H2: 0.024680306 | I2: 0.91241659 | J2: 4.2994231 | K2: 45
A3: SUP002 | B3: Supplier 02 | C3: National | D3: 16363 | E3: 0.85714673 | F3: 5 | G3: 1785 | H3: 0.00414364 | I3: 0.95107983 | J3: 23.586712 | K3: 30
A4: SUP003 | B4: Supplier 03 | C4: Domestic | D4: 11420 | E4: 1.0469926 | F4: 28 | G4: 4217 | H4: 0.0022685196 | I4: 0.85322874 | J4: 14.069817 | K4: 30
A5: SUP004 | B5: Supplier 04 | C5: Domestic | D5: 7747 | E5: 0.94654474 | F5: 17 | G5: 3105 | H5: 0.0095876037 | I5: 0.92199282 | J5: 15.625535 | K5: 45
A6: SUP005 | B6: Supplier 05 | C6: National | D6: 13838 | E6: 0.86820965 | F6: 9 | G6: 2535 | H6: 0.037803667 | I6: 0.92886035 | J6: 10.86458 | K6: 30
A7: SUP006 | B7: Supplier 06 | C7: Domestic | D7: 27619 | E7: 0.976061 | F7: 9 | G7: 2656 | H7: 0.033661407 | I7: 0.87427105 | J7: 10.994394 | K7: 30
A8: SUP007 | B8: Supplier 07 | C8: Regional | D8: 24457 | E8: 0.97006235 | F8: 24 | G8: 3943 | H8: 0.0090244693 | I8: 0.98574185 | J8: 19.828055 | K8: 30
A9: SUP008 | B9: Supplier 08 | C9: Domestic | D9: 5995 | E9: 1.03916 | F9: 18 | G9: 3442 | H9: 0.0053627151 | I9: 0.8774376 | J9: 3.0402276 | K9: 90
A10: SUP009 | B10: Supplier 09 | C10: Domestic | D10: 13529 | E10: 1.0158769 | F10: 26 | G10: 4093 | H10: 0.038679702 | I10: 0.93498479 | J10: 8.3479812 | K10: 90
A11: SUP010 | B11: Supplier 10 | C11: National | D11: 21448 | E11: 0.80625456 | F11: 11 | G11: 2127 | H11: 0.013152551 | I11: 0.85197118 | J11: 6.5733753 | K11: 45
A12: SUP011 | B12: Supplier 11 | C12: Regional | D12: 17666 | E12: 0.82961786 | F12: 9 | G12: 3199 | H12: 0.03479793 | I12: 0.93726174 | J12: 9.6106546 | K12: 90
A13: SUP012 | B13: Supplier 12 | C13: Regional | D13: 15965 | E13: 1.1548851 | F13: 3 | G13: 2790 | H13: 0.030909832 | I13: 0.92857881 | J13: 19.732245 | K13: 45
... A31: SUP030 | B31: Supplier 30 | C31: Regional | D31: 10895 | E31: 1.0524555 | F31: 4 | G31: 4993 | H31: 0.026513928 | I31: 0.94364937 | J31: 21.875854 | K31: 60

Sheet 06_raw_machine_oee
A1: Machine_ID | B1: Average_Availability | C1: Average_Performance | D1: Average_Quality | E1: Average_OEE
A2: M001 | B2: 0.8657 | C2: 0.89089217 | D2: 0.98706316 | E2: 0.76129474
A3: M002 | B3: 0.8367 | C3: 0.89980774 | D3: 0.98745625 | E3: 0.74339375
A4: M003 | B4: 0.8695 | C4: 0.88174868 | D4: 0.98556429 | E4: 0.75560714
A5: M004 | B5: 0.8498 | C5: 0.89109387 | D5: 0.98591429 | E5: 0.74658571
A6: M005 | B6: 0.8538 | C6: 0.88083076 | D6: 0.98434375 | E6: 0.74025
A7: M006 | B7: 0.8434 | C7: 0.89914977 | D7: 0.98716538 | E7: 0.74857308
A8: M007 | B8: 0.8801 | C8: 0.8920609 | D8: 0.98529 | E8: 0.77354
A9: M008 | B9: 0.9076 | C9: 0.91668988 | D9: 0.98773 | E9: 0.82191
A10: M009 | B10: 0.8745 | C10: 0.89300765 | D10: 0.97657143 | E10: 0.76257143
A11: M010 | B11: 0.8805 | C11: 0.86753621 | D11: 0.988675 | E11: 0.7552875
A12: M011 | B12: 0.8763 | C12: 0.89317048 | D12: 0.98323333 | E12: 0.769675
A13: M012 | B13: 0.8797 | C13: 0.88822302 | D13: 0.98475 | E13: 0.769425
... A26: M025 | B26: 0.8903 | C26: 0.90062663 | D26: 0.99015714 | E26: 0.79405714

Sheet 07_raw_labour
A1: Metric | B1: Value
A2: Total Operators | B2: 30
A3: Effective Labour Capacity (Hours) | B3: 132480
A4: Total Required Labour Hours | B4: 121282.73
A5: Labour Utilization (%) | B5: 91.547956
A6: Labour Surplus / Shortage (Hours) | B6: 11197.267
A7: Total Scheduled Hours per Machine | B7: 4800

Sheet 08_demand_planning
A1: Component_ID | B1: Component_Name | C1: Product_Family | D1: Category | E1: Sourcing_Type | F1: Criticality | G1: Monthly_Demand | H1: Demand_Growth_Rate | I1: Forecast_Demand | J1: Annual_Demand | K1: Demand_Variability | L1: Demand_Growth_Impact
A2: =tblComponents[Component_ID] -> C001 | B2: =tblComponents[Component_Name] -> Component 001 | C2: =tblComponents[Product_Family] -> Powertrain | D2: =tblComponents[Category] -> Electrical | E2: =tblComponents[Sourcing_Type] -> Make | F2: =tblComponents[Criticality] -> Medium | G2: =tblComponents[Monthly_Demand] -> 557 | H2: =tblComponents[Demand_Growth_Rate] -> 0.17880343 | I2: =tblComponents[Forecast_Demand] -> 657 | J2: =tblComponents[Annual_Demand] -> 5924 | K2: =tblComponents[Demand_Variability] -> 0.1725 | L2: =I2-G2 -> 100 | N2: Summary Total | O2: Value | Q2: Summary Table: | U2: Chart: | V2: Forecast Demand by Sourcing Type
A3: =tblComponents[Component_ID] -> C002 | B3: =tblComponents[Component_Name] -> Component 002 | C3: =tblComponents[Product_Family] -> Chassis | D3: =tblComponents[Category] -> Metal | E3: =tblComponents[Sourcing_Type] -> Make | F3: =tblComponents[Criticality] -> Low | G3: =tblComponents[Monthly_Demand] -> 688 | H3: =tblComponents[Demand_Growth_Rate] -> 0.13447423 | I3: =tblComponents[Forecast_Demand] -> 781 | J3: =tblComponents[Annual_Demand] -> 45830 | K3: =tblComponents[Demand_Variability] -> 0.2459 | L3: =I3-G3 -> 93 | N3: Total Components | O3: =COUNTA(tblComponents[Component_ID]) -> 500 | Q3: Sourcing Type | R3: Components | S3: Forecast Demand
A4: =tblComponents[Component_ID] -> C003 | B4: =tblComponents[Component_Name] -> Component 003 | C4: =tblComponents[Product_Family] -> Electrical Systems | D4: =tblComponents[Category] -> Metal | E4: =tblComponents[Sourcing_Type] -> Make | F4: =tblComponents[Criticality] -> Medium | G4: =tblComponents[Monthly_Demand] -> 284 | H4: =tblComponents[Demand_Growth_Rate] -> 0.035469917 | I4: =tblComponents[Forecast_Demand] -> 294 | J4: =tblComponents[Annual_Demand] -> 77893 | K4: =tblComponents[Demand_Variability] -> 0.1428 | L4: =I4-G4 -> 10 | N4: Total Monthly Demand | O4: =SUM(tblComponents[Monthly_Demand]) -> 505526 | Q4: Make | R4: =COUNTIF(tblComponents[Sourcing_Type],"Make") -> 300 | S4: =SUMIF(tblComponents[Sourcing_Type],"Make",tblComponents[Forecast_Demand]) -> 312250
A5: =tblComponents[Component_ID] -> C004 | B5: =tblComponents[Component_Name] -> Component 004 | C5: =tblComponents[Product_Family] -> Powertrain | D5: =tblComponents[Category] -> Metal | E5: =tblComponents[Sourcing_Type] -> Make | F5: =tblComponents[Criticality] -> High | G5: =tblComponents[Monthly_Demand] -> 1473 | H5: =tblComponents[Demand_Growth_Rate] -> 0.072903969 | I5: =tblComponents[Forecast_Demand] -> 1580 | J5: =tblComponents[Annual_Demand] -> 18650 | K5: =tblComponents[Demand_Variability] -> 0.1407 | L5: =I5-G5 -> 107 | N5: Total Forecast Demand | O5: =SUM(tblComponents[Forecast_Demand]) -> 544289 | Q5: Buy | R5: =COUNTIF(tblComponents[Sourcing_Type],"Buy") -> 200 | S5: =SUMIF(tblComponents[Sourcing_Type],"Buy",tblComponents[Forecast_Demand]) -> 232039
A6: =tblComponents[Component_ID] -> C005 | B6: =tblComponents[Component_Name] -> Component 005 | C6: =tblComponents[Product_Family] -> Powertrain | D6: =tblComponents[Category] -> Metal | E6: =tblComponents[Sourcing_Type] -> Make | F6: =tblComponents[Criticality] -> Medium | G6: =tblComponents[Monthly_Demand] -> 1301 | H6: =tblComponents[Demand_Growth_Rate] -> 0.015223406 | I6: =tblComponents[Forecast_Demand] -> 1321 | J6: =tblComponents[Annual_Demand] -> 15691 | K6: =tblComponents[Demand_Variability] -> 0.1385 | L6: =I6-G6 -> 20 | N6: Total Annual Demand | O6: =SUM(tblComponents[Annual_Demand]) -> 21082951 | Q6: Total | R6: =COUNTA(tblComponents[Component_ID]) -> 500 | S6: =SUM(tblComponents[Forecast_Demand]) -> 544289
A7: =tblComponents[Component_ID] -> C006 | B7: =tblComponents[Component_Name] -> Component 006 | C7: =tblComponents[Product_Family] -> Interior | D7: =tblComponents[Category] -> Metal | E7: =tblComponents[Sourcing_Type] -> Make | F7: =tblComponents[Criticality] -> Medium | G7: =tblComponents[Monthly_Demand] -> 835 | H7: =tblComponents[Demand_Growth_Rate] -> 0.11060482 | I7: =tblComponents[Forecast_Demand] -> 927 | J7: =tblComponents[Annual_Demand] -> 45062 | K7: =tblComponents[Demand_Variability] -> 0.1685 | L7: =I7-G7 -> 92 | N7: Make Components | O7: =COUNTIF(tblComponents[Sourcing_Type],"Make") -> 300
A8: =tblComponents[Component_ID] -> C007 | B8: =tblComponents[Component_Name] -> Component 007 | C8: =tblComponents[Product_Family] -> Electrical Systems | D8: =tblComponents[Category] -> Electrical | E8: =tblComponents[Sourcing_Type] -> Make | F8: =tblComponents[Criticality] -> Medium | G8: =tblComponents[Monthly_Demand] -> 1428 | H8: =tblComponents[Demand_Growth_Rate] -> 0.15280104 | I8: =tblComponents[Forecast_Demand] -> 1646 | J8: =tblComponents[Annual_Demand] -> 15931 | K8: =tblComponents[Demand_Variability] -> 0.1549 | L8: =I8-G8 -> 218 | N8: Buy Components | O8: =COUNTIF(tblComponents[Sourcing_Type],"Buy") -> 200
A9: =tblComponents[Component_ID] -> C008 | B9: =tblComponents[Component_Name] -> Component 008 | C9: =tblComponents[Product_Family] -> Electrical Systems | D9: =tblComponents[Category] -> Electrical | E9: =tblComponents[Sourcing_Type] -> Make | F9: =tblComponents[Criticality] -> High | G9: =tblComponents[Monthly_Demand] -> 511 | H9: =tblComponents[Demand_Growth_Rate] -> -0.0248055 | I9: =tblComponents[Forecast_Demand] -> 498 | J9: =tblComponents[Annual_Demand] -> 46730 | K9: =tblComponents[Demand_Variability] -> 0.2296 | L9: =I9-G9 -> -13 | Q9: Demand Growth Analysis
A10: =tblComponents[Component_ID] -> C009 | B10: =tblComponents[Component_Name] -> Component 009 | C10: =tblComponents[Product_Family] -> Powertrain | D10: =tblComponents[Category] -> Electrical | E10: =tblComponents[Sourcing_Type] -> Make | F10: =tblComponents[Criticality] -> High | G10: =tblComponents[Monthly_Demand] -> 189 | H10: =tblComponents[Demand_Growth_Rate] -> 0.035156142 | I10: =tblComponents[Forecast_Demand] -> 196 | J10: =tblComponents[Annual_Demand] -> 40692 | K10: =tblComponents[Demand_Variability] -> 0.1659 | L10: =I10-G10 -> 7 | Q10: Metric | R10: Value
A11: =tblComponents[Component_ID] -> C010 | B11: =tblComponents[Component_Name] -> Component 010 | C11: =tblComponents[Product_Family] -> Electrical Systems | D11: =tblComponents[Category] -> Electrical | E11: =tblComponents[Sourcing_Type] -> Make | F11: =tblComponents[Criticality] -> Low | G11: =tblComponents[Monthly_Demand] -> 1728 | H11: =tblComponents[Demand_Growth_Rate] -> 0.15087023 | I11: =tblComponents[Forecast_Demand] -> 1989 | J11: =tblComponents[Annual_Demand] -> 77295 | K11: =tblComponents[Demand_Variability] -> 0.1663 | L11: =I11-G11 -> 261 | Q11: Current Monthly Demand | R11: =SUM(tblComponents[Monthly_Demand]) -> 505526
A12: =tblComponents[Component_ID] -> C011 | B12: =tblComponents[Component_Name] -> Component 011 | C12: =tblComponents[Product_Family] -> Powertrain | D12: =tblComponents[Category] -> Electrical | E12: =tblComponents[Sourcing_Type] -> Make | F12: =tblComponents[Criticality] -> Low | G12: =tblComponents[Monthly_Demand] -> 1477 | H12: =tblComponents[Demand_Growth_Rate] -> 0.012504112 | I12: =tblComponents[Forecast_Demand] -> 1495 | J12: =tblComponents[Annual_Demand] -> 24054 | K12: =tblComponents[Demand_Variability] -> 0.1035 | L12: =I12-G12 -> 18 | Q12: Forecast Monthly Demand | R12: =SUM(tblComponents[Forecast_Demand]) -> 544289
A13: =tblComponents[Component_ID] -> C012 | B13: =tblComponents[Component_Name] -> Component 012 | C13: =tblComponents[Product_Family] -> Interior | D13: =tblComponents[Category] -> Metal | E13: =tblComponents[Sourcing_Type] -> Make | F13: =tblComponents[Criticality] -> Medium | G13: =tblComponents[Monthly_Demand] -> 454 | H13: =tblComponents[Demand_Growth_Rate] -> -0.024219033 | I13: =tblComponents[Forecast_Demand] -> 443 | J13: =tblComponents[Annual_Demand] -> 64057 | K13: =tblComponents[Demand_Variability] -> 0.2471 | L13: =I13-G13 -> -11 | Q13: Additional Monthly Demand | R13: =R12 - R11 -> 38763
A14: =tblComponents[Component_ID] -> C013 | B14: =tblComponents[Component_Name] -> Component 013 | C14: =tblComponents[Product_Family] -> Electrical Systems | D14: =tblComponents[Category] -> Electrical | E14: =tblComponents[Sourcing_Type] -> Make | F14: =tblComponents[Criticality] -> Low | G14: =tblComponents[Monthly_Demand] -> 895 | H14: =tblComponents[Demand_Growth_Rate] -> 0.18963537 | I14: =tblComponents[Forecast_Demand] -> 1065 | J14: =tblComponents[Annual_Demand] -> 96983 | K14: =tblComponents[Demand_Variability] -> 0.1225 | L14: =I14-G14 -> 170 | Q14: Forecast Growth % | R14: =(R12/R11)-1 -> 0.076678549
A15: =tblComponents[Component_ID] -> C014 | B15: =tblComponents[Component_Name] -> Component 014 | C15: =tblComponents[Product_Family] -> Chassis | D15: =tblComponents[Category] -> Electrical | E15: =tblComponents[Sourcing_Type] -> Make | F15: =tblComponents[Criticality] -> Medium | G15: =tblComponents[Monthly_Demand] -> 643 | H15: =tblComponents[Demand_Growth_Rate] -> 0.06211138 | I15: =tblComponents[Forecast_Demand] -> 683 | J15: =tblComponents[Annual_Demand] -> 56107 | K15: =tblComponents[Demand_Variability] -> 0.0925 | L15: =I15-G15 -> 40
A16: =tblComponents[Component_ID] -> C015 | B16: =tblComponents[Component_Name] -> Component 015 | C16: =tblComponents[Product_Family] -> Chassis | D16: =tblComponents[Category] -> Electrical | E16: =tblComponents[Sourcing_Type] -> Make | F16: =tblComponents[Criticality] -> Medium | G16: =tblComponents[Monthly_Demand] -> 208 | H16: =tblComponents[Demand_Growth_Rate] -> 0.18273228 | I16: =tblComponents[Forecast_Demand] -> 246 | J16: =tblComponents[Annual_Demand] -> 32695 | K16: =tblComponents[Demand_Variability] -> 0.1927 | L16: =I16-G16 -> 38
A17: =tblComponents[Component_ID] -> C016 | B17: =tblComponents[Component_Name] -> Component 016 | C17: =tblComponents[Product_Family] -> Interior | D17: =tblComponents[Category] -> Metal | E17: =tblComponents[Sourcing_Type] -> Make | F17: =tblComponents[Criticality] -> Medium | G17: =tblComponents[Monthly_Demand] -> 338 | H17: =tblComponents[Demand_Growth_Rate] -> -0.014252079 | I17: =tblComponents[Forecast_Demand] -> 333 | J17: =tblComponents[Annual_Demand] -> 56347 | K17: =tblComponents[Demand_Variability] -> 0.1812 | L17: =I17-G17 -> -5
A18: =tblComponents[Component_ID] -> C017 | B18: =tblComponents[Component_Name] -> Component 017 | C18: =tblComponents[Product_Family] -> Electrical Systems | D18: =tblComponents[Category] -> Metal | E18: =tblComponents[Sourcing_Type] -> Make | F18: =tblComponents[Criticality] -> Medium | G18: =tblComponents[Monthly_Demand] -> 1945 | H18: =tblComponents[Demand_Growth_Rate] -> 0.17297423 | I18: =tblComponents[Forecast_Demand] -> 2281 | J18: =tblComponents[Annual_Demand] -> 53906 | K18: =tblComponents[Demand_Variability] -> 0.1506 | L18: =I18-G18 -> 336
A19: =tblComponents[Component_ID] -> C018 | B19: =tblComponents[Component_Name] -> Component 018 | C19: =tblComponents[Product_Family] -> Electrical Systems | D19: =tblComponents[Category] -> Metal | E19: =tblComponents[Sourcing_Type] -> Make | F19: =tblComponents[Criticality] -> Low | G19: =tblComponents[Monthly_Demand] -> 244 | H19: =tblComponents[Demand_Growth_Rate] -> 0.18681214 | I19: =tblComponents[Forecast_Demand] -> 290 | J19: =tblComponents[Annual_Demand] -> 33257 | K19: =tblComponents[Demand_Variability] -> 0.1518 | L19: =I19-G19 -> 46
A20: =tblComponents[Component_ID] -> C019 | B20: =tblComponents[Component_Name] -> Component 019 | C20: =tblComponents[Product_Family] -> Body & Exterior | D20: =tblComponents[Category] -> Metal | E20: =tblComponents[Sourcing_Type] -> Make | F20: =tblComponents[Criticality] -> Medium | G20: =tblComponents[Monthly_Demand] -> 590 | H20: =tblComponents[Demand_Growth_Rate] -> 0.012181039 | I20: =tblComponents[Forecast_Demand] -> 597 | J20: =tblComponents[Annual_Demand] -> 68230 | K20: =tblComponents[Demand_Variability] -> 0.2135 | L20: =I20-G20 -> 7
A21: =tblComponents[Component_ID] -> C020 | B21: =tblComponents[Component_Name] -> Component 020 | C21: =tblComponents[Product_Family] -> Chassis | D21: =tblComponents[Category] -> Metal | E21: =tblComponents[Sourcing_Type] -> Make | F21: =tblComponents[Criticality] -> Medium | G21: =tblComponents[Monthly_Demand] -> 416 | H21: =tblComponents[Demand_Growth_Rate] -> 0.15569759 | I21: =tblComponents[Forecast_Demand] -> 481 | J21: =tblComponents[Annual_Demand] -> 40491 | K21: =tblComponents[Demand_Variability] -> 0.1133 | L21: =I21-G21 -> 65
A22: =tblComponents[Component_ID] -> C021 | B22: =tblComponents[Component_Name] -> Component 021 | C22: =tblComponents[Product_Family] -> Body & Exterior | D22: =tblComponents[Category] -> Metal | E22: =tblComponents[Sourcing_Type] -> Make | F22: =tblComponents[Criticality] -> Medium | G22: =tblComponents[Monthly_Demand] -> 1928 | H22: =tblComponents[Demand_Growth_Rate] -> 0.0058989596 | I22: =tblComponents[Forecast_Demand] -> 1939 | J22: =tblComponents[Annual_Demand] -> 38165 | K22: =tblComponents[Demand_Variability] -> 0.2194 | L22: =I22-G22 -> 11
A23: =tblComponents[Component_ID] -> C022 | B23: =tblComponents[Component_Name] -> Component 022 | C23: =tblComponents[Product_Family] -> Powertrain | D23: =tblComponents[Category] -> Electrical | E23: =tblComponents[Sourcing_Type] -> Make | F23: =tblComponents[Criticality] -> Low | G23: =tblComponents[Monthly_Demand] -> 702 | H23: =tblComponents[Demand_Growth_Rate] -> 0.17977893 | I23: =tblComponents[Forecast_Demand] -> 828 | J23: =tblComponents[Annual_Demand] -> 55566 | K23: =tblComponents[Demand_Variability] -> 0.1903 | L23: =I23-G23 -> 126
A24: =tblComponents[Component_ID] -> C023 | B24: =tblComponents[Component_Name] -> Component 023 | C24: =tblComponents[Product_Family] -> Body & Exterior | D24: =tblComponents[Category] -> Metal | E24: =tblComponents[Sourcing_Type] -> Make | F24: =tblComponents[Criticality] -> High | G24: =tblComponents[Monthly_Demand] -> 1012 | H24: =tblComponents[Demand_Growth_Rate] -> 0.10688952 | I24: =tblComponents[Forecast_Demand] -> 1120 | J24: =tblComponents[Annual_Demand] -> 60134 | K24: =tblComponents[Demand_Variability] -> 0.1512 | L24: =I24-G24 -> 108
A25: =tblComponents[Component_ID] -> C024 | B25: =tblComponents[Component_Name] -> Component 024 | C25: =tblComponents[Product_Family] -> Interior | D25: =tblComponents[Category] -> Metal | E25: =tblComponents[Sourcing_Type] -> Make | F25: =tblComponents[Criticality] -> Low | G25: =tblComponents[Monthly_Demand] -> 255 | H25: =tblComponents[Demand_Growth_Rate] -> 0.033915016 | I25: =tblComponents[Forecast_Demand] -> 264 | J25: =tblComponents[Annual_Demand] -> 40345 | K25: =tblComponents[Demand_Variability] -> 0.1579 | L25: =I25-G25 -> 9
A26: =tblComponents[Component_ID] -> C025 | B26: =tblComponents[Component_Name] -> Component 025 | C26: =tblComponents[Product_Family] -> Body & Exterior | D26: =tblComponents[Category] -> Metal | E26: =tblComponents[Sourcing_Type] -> Make | F26: =tblComponents[Criticality] -> High | G26: =tblComponents[Monthly_Demand] -> 1239 | H26: =tblComponents[Demand_Growth_Rate] -> 0.19655269 | I26: =tblComponents[Forecast_Demand] -> 1483 | J26: =tblComponents[Annual_Demand] -> 71185 | K26: =tblComponents[Demand_Variability] -> 0.1236 | L26: =I26-G26 -> 244
... A501: =tblComponents[Component_ID] -> C500 | B501: =tblComponents[Component_Name] -> Component 500 | C501: =tblComponents[Product_Family] -> Powertrain | D501: =tblComponents[Category] -> Metal | E501: =tblComponents[Sourcing_Type] -> Buy | F501: =tblComponents[Criticality] -> Medium | G501: =tblComponents[Monthly_Demand] -> 462 | H501: =tblComponents[Demand_Growth_Rate] -> -0.021639796 | I501: =tblComponents[Forecast_Demand] -> 452 | J501: =tblComponents[Annual_Demand] -> 94140 | K501: =tblComponents[Demand_Variability] -> 0.1418 | L501: =I501-G501 -> -10

Sheet 09_inventory_production_reqmnt
A1: Component_ID | B1: Component_Name | C1: Product_Family | D1: Sourcing_Type | E1: Criticality | F1: Forecast_Demand | G1: Opening_Inventory | H1: Safety_Stock | I1: Net_Requirement | J1: Defect_Rate | K1: Gross_Requirement | L1: Fulfillment_Type | M1: Production_Procurement_Requirement
A2: =tblComponents[Component_ID] -> C001 | B2: =tblComponents[Component_Name] -> Component 001 | C2: =tblComponents[Product_Family] -> Powertrain | D2: =tblComponents[Sourcing_Type] -> Make | E2: =tblComponents[Criticality] -> Medium | F2: =tblComponents[Forecast_Demand] -> 657 | G2: =tblComponents[Opening_Inventory] -> 1130 | H2: =tblComponents[Safety_Stock] -> 98 | I2: =MAX(0,F2+H2-G2) -> 0 | J2: =tblComponents[Defect_Rate] -> 0.0151 | K2: =IFERROR(I2/(1-J2),0) -> 0 | L2: =IF(D2="Make","Production","Procurement") -> Production | M2: =K2 -> 0 | O2: Fulfillment Summary | S2: Chart: | T2: Requirement by Fulfillment Type
A3: =tblComponents[Component_ID] -> C002 | B3: =tblComponents[Component_Name] -> Component 002 | C3: =tblComponents[Product_Family] -> Chassis | D3: =tblComponents[Sourcing_Type] -> Make | E3: =tblComponents[Criticality] -> Low | F3: =tblComponents[Forecast_Demand] -> 781 | G3: =tblComponents[Opening_Inventory] -> 4186 | H3: =tblComponents[Safety_Stock] -> 1546 | I3: =MAX(0,F3+H3-G3) -> 0 | J3: =tblComponents[Defect_Rate] -> 0.0054 | K3: =IFERROR(I3/(1-J3),0) -> 0 | L3: =IF(D3="Make","Production","Procurement") -> Production | M3: =K3 -> 0 | O3: Fulfillment Type | P3: Components | Q3: Requirement
A4: =tblComponents[Component_ID] -> C003 | B4: =tblComponents[Component_Name] -> Component 003 | C4: =tblComponents[Product_Family] -> Electrical Systems | D4: =tblComponents[Sourcing_Type] -> Make | E4: =tblComponents[Criticality] -> Medium | F4: =tblComponents[Forecast_Demand] -> 294 | G4: =tblComponents[Opening_Inventory] -> 7776 | H4: =tblComponents[Safety_Stock] -> 1143 | I4: =MAX(0,F4+H4-G4) -> 0 | J4: =tblComponents[Defect_Rate] -> 0.0169 | K4: =IFERROR(I4/(1-J4),0) -> 0 | L4: =IF(D4="Make","Production","Procurement") -> Production | M4: =K4 -> 0 | O4: Production | P4: =COUNTIF(L:L,"Production") -> 300 | Q4: =SUMIF(L:L,"Production",M:M) -> 18065.531
A5: =tblComponents[Component_ID] -> C004 | B5: =tblComponents[Component_Name] -> Component 004 | C5: =tblComponents[Product_Family] -> Powertrain | D5: =tblComponents[Sourcing_Type] -> Make | E5: =tblComponents[Criticality] -> High | F5: =tblComponents[Forecast_Demand] -> 1580 | G5: =tblComponents[Opening_Inventory] -> 2893 | H5: =tblComponents[Safety_Stock] -> 253 | I5: =MAX(0,F5+H5-G5) -> 0 | J5: =tblComponents[Defect_Rate] -> 0.0069 | K5: =IFERROR(I5/(1-J5),0) -> 0 | L5: =IF(D5="Make","Production","Procurement") -> Production | M5: =K5 -> 0 | O5: Procurement | P5: =COUNTIF(L:L,"Procurement") -> 200 | Q5: =SUMIF(L:L,"Procurement",M:M) -> 13941
A6: =tblComponents[Component_ID] -> C005 | B6: =tblComponents[Component_Name] -> Component 005 | C6: =tblComponents[Product_Family] -> Powertrain | D6: =tblComponents[Sourcing_Type] -> Make | E6: =tblComponents[Criticality] -> Medium | F6: =tblComponents[Forecast_Demand] -> 1321 | G6: =tblComponents[Opening_Inventory] -> 2586 | H6: =tblComponents[Safety_Stock] -> 305 | I6: =MAX(0,F6+H6-G6) -> 0 | J6: =tblComponents[Defect_Rate] -> 0.0276 | K6: =IFERROR(I6/(1-J6),0) -> 0 | L6: =IF(D6="Make","Production","Procurement") -> Production | M6: =K6 -> 0 | O6: Total | Q6: =SUM(M:M) -> 32006.531
A7: =tblComponents[Component_ID] -> C006 | B7: =tblComponents[Component_Name] -> Component 006 | C7: =tblComponents[Product_Family] -> Interior | D7: =tblComponents[Sourcing_Type] -> Make | E7: =tblComponents[Criticality] -> Medium | F7: =tblComponents[Forecast_Demand] -> 927 | G7: =tblComponents[Opening_Inventory] -> 8535 | H7: =tblComponents[Safety_Stock] -> 1008 | I7: =MAX(0,F7+H7-G7) -> 0 | J7: =tblComponents[Defect_Rate] -> 0.0161 | K7: =IFERROR(I7/(1-J7),0) -> 0 | L7: =IF(D7="Make","Production","Procurement") -> Production | M7: =K7 -> 0
A8: =tblComponents[Component_ID] -> C007 | B8: =tblComponents[Component_Name] -> Component 007 | C8: =tblComponents[Product_Family] -> Electrical Systems | D8: =tblComponents[Sourcing_Type] -> Make | E8: =tblComponents[Criticality] -> Medium | F8: =tblComponents[Forecast_Demand] -> 1646 | G8: =tblComponents[Opening_Inventory] -> 1286 | H8: =tblComponents[Safety_Stock] -> 361 | I8: =MAX(0,F8+H8-G8) -> 721 | J8: =tblComponents[Defect_Rate] -> 0.0056 | K8: =IFERROR(I8/(1-J8),0) -> 725.06034 | L8: =IF(D8="Make","Production","Procurement") -> Production | M8: =K8 -> 725.06034 | O8: Inventory Summary
A9: =tblComponents[Component_ID] -> C008 | B9: =tblComponents[Component_Name] -> Component 008 | C9: =tblComponents[Product_Family] -> Electrical Systems | D9: =tblComponents[Sourcing_Type] -> Make | E9: =tblComponents[Criticality] -> High | F9: =tblComponents[Forecast_Demand] -> 498 | G9: =tblComponents[Opening_Inventory] -> 7930 | H9: =tblComponents[Safety_Stock] -> 1171 | I9: =MAX(0,F9+H9-G9) -> 0 | J9: =tblComponents[Defect_Rate] -> 0.0241 | K9: =IFERROR(I9/(1-J9),0) -> 0 | L9: =IF(D9="Make","Production","Procurement") -> Production | M9: =K9 -> 0 | O9: Metric | P9: Value
A10: =tblComponents[Component_ID] -> C009 | B10: =tblComponents[Component_Name] -> Component 009 | C10: =tblComponents[Product_Family] -> Powertrain | D10: =tblComponents[Sourcing_Type] -> Make | E10: =tblComponents[Criticality] -> High | F10: =tblComponents[Forecast_Demand] -> 196 | G10: =tblComponents[Opening_Inventory] -> 6543 | H10: =tblComponents[Safety_Stock] -> 815 | I10: =MAX(0,F10+H10-G10) -> 0 | J10: =tblComponents[Defect_Rate] -> 0.0139 | K10: =IFERROR(I10/(1-J10),0) -> 0 | L10: =IF(D10="Make","Production","Procurement") -> Production | M10: =K10 -> 0 | O10: Total Forecast Demand | P10: =SUM(F:F) -> 544289
A11: =tblComponents[Component_ID] -> C010 | B11: =tblComponents[Component_Name] -> Component 010 | C11: =tblComponents[Product_Family] -> Electrical Systems | D11: =tblComponents[Sourcing_Type] -> Make | E11: =tblComponents[Criticality] -> Low | F11: =tblComponents[Forecast_Demand] -> 1989 | G11: =tblComponents[Opening_Inventory] -> 4604 | H11: =tblComponents[Safety_Stock] -> 1505 | I11: =MAX(0,F11+H11-G11) -> 0 | J11: =tblComponents[Defect_Rate] -> 0.0037 | K11: =IFERROR(I11/(1-J11),0) -> 0 | L11: =IF(D11="Make","Production","Procurement") -> Production | M11: =K11 -> 0 | O11: Total Opening Inventory | P11: =SUM(G:G) -> 2635736
A12: =tblComponents[Component_ID] -> C011 | B12: =tblComponents[Component_Name] -> Component 011 | C12: =tblComponents[Product_Family] -> Powertrain | D12: =tblComponents[Sourcing_Type] -> Make | E12: =tblComponents[Criticality] -> Low | F12: =tblComponents[Forecast_Demand] -> 1495 | G12: =tblComponents[Opening_Inventory] -> 2600 | H12: =tblComponents[Safety_Stock] -> 412 | I12: =MAX(0,F12+H12-G12) -> 0 | J12: =tblComponents[Defect_Rate] -> 0.0189 | K12: =IFERROR(I12/(1-J12),0) -> 0 | L12: =IF(D12="Make","Production","Procurement") -> Production | M12: =K12 -> 0 | O12: Total Safety Stock | P12: =SUM(H:H) -> 424612
A13: =tblComponents[Component_ID] -> C012 | B13: =tblComponents[Component_Name] -> Component 012 | C13: =tblComponents[Product_Family] -> Interior | D13: =tblComponents[Sourcing_Type] -> Make | E13: =tblComponents[Criticality] -> Medium | F13: =tblComponents[Forecast_Demand] -> 443 | G13: =tblComponents[Opening_Inventory] -> 5920 | H13: =tblComponents[Safety_Stock] -> 1705 | I13: =MAX(0,F13+H13-G13) -> 0 | J13: =tblComponents[Defect_Rate] -> 0.0078 | K13: =IFERROR(I13/(1-J13),0) -> 0 | L13: =IF(D13="Make","Production","Procurement") -> Production | M13: =K13 -> 0 | O13: Total Net Requirement | P13: =SUM(I:I) -> 31745
A14: =tblComponents[Component_ID] -> C013 | B14: =tblComponents[Component_Name] -> Component 013 | C14: =tblComponents[Product_Family] -> Electrical Systems | D14: =tblComponents[Sourcing_Type] -> Make | E14: =tblComponents[Criticality] -> Low | F14: =tblComponents[Forecast_Demand] -> 1065 | G14: =tblComponents[Opening_Inventory] -> 9279 | H14: =tblComponents[Safety_Stock] -> 1282 | I14: =MAX(0,F14+H14-G14) -> 0 | J14: =tblComponents[Defect_Rate] -> 0.0205 | K14: =IFERROR(I14/(1-J14),0) -> 0 | L14: =IF(D14="Make","Production","Procurement") -> Production | M14: =K14 -> 0 | O14: Total Gross Requirement | P14: =SUM(K:K) -> 32006.531
A15: =tblComponents[Component_ID] -> C014 | B15: =tblComponents[Component_Name] -> Component 014 | C15: =tblComponents[Product_Family] -> Chassis | D15: =tblComponents[Sourcing_Type] -> Make | E15: =tblComponents[Criticality] -> Medium | F15: =tblComponents[Forecast_Demand] -> 683 | G15: =tblComponents[Opening_Inventory] -> 11078 | H15: =tblComponents[Safety_Stock] -> 586 | I15: =MAX(0,F15+H15-G15) -> 0 | J15: =tblComponents[Defect_Rate] -> 0.0208 | K15: =IFERROR(I15/(1-J15),0) -> 0 | L15: =IF(D15="Make","Production","Procurement") -> Production | M15: =K15 -> 0
A16: =tblComponents[Component_ID] -> C015 | B16: =tblComponents[Component_Name] -> Component 015 | C16: =tblComponents[Product_Family] -> Chassis | D16: =tblComponents[Sourcing_Type] -> Make | E16: =tblComponents[Criticality] -> Medium | F16: =tblComponents[Forecast_Demand] -> 246 | G16: =tblComponents[Opening_Inventory] -> 4787 | H16: =tblComponents[Safety_Stock] -> 822 | I16: =MAX(0,F16+H16-G16) -> 0 | J16: =tblComponents[Defect_Rate] -> 0.0245 | K16: =IFERROR(I16/(1-J16),0) -> 0 | L16: =IF(D16="Make","Production","Procurement") -> Production | M16: =K16 -> 0
A17: =tblComponents[Component_ID] -> C016 | B17: =tblComponents[Component_Name] -> Component 016 | C17: =tblComponents[Product_Family] -> Interior | D17: =tblComponents[Sourcing_Type] -> Make | E17: =tblComponents[Criticality] -> Medium | F17: =tblComponents[Forecast_Demand] -> 333 | G17: =tblComponents[Opening_Inventory] -> 8883 | H17: =tblComponents[Safety_Stock] -> 1066 | I17: =MAX(0,F17+H17-G17) -> 0 | J17: =tblComponents[Defect_Rate] -> 0.0135 | K17: =IFERROR(I17/(1-J17),0) -> 0 | L17: =IF(D17="Make","Production","Procurement") -> Production | M17: =K17 -> 0
